Workbook

Sheet Sprint 1
A1: Project name: | C1: XÂY DỰNG HỆ THỐNG QUẢN LÝ NHÂN SỰ CHO DOANH NGHIỆP NHỎ TÍCH HỢP CHATBOT AI HỖ TRỢ TRA CỨU THÔNG TIN | F1: Kết thúc
A2: Module name: | C2: Sprint 1 | F2: Tăng ca
A3: Start date: | C3: 46101 | F3: Muộn
A4: End date: | C4: 46121 | F4: Chậm tiến độ
F5: Trước thời hạn
B6: SPRINT 1 REPORT
B7: No | C7: Thành viên | D7: Thực tế | E7: Ước tính
B8: 1 | C8: Lê Xuân Khoa | D8: =SUMIF($E$16:$F$81,"Khoa",$G$16:$G$81)+SUMIF($E$16:$F$81,"All Team",$G$16:$G$81)/5 -> 33 | E8: =SUMIF($E$16:$F$81,"Khoa",$H$16:$H$81)+SUMIF($E$16:$F$81,"All Team",$H$16:$H$81)/5 -> 34
B9: 2 | C9: Hoàng Minh Khánh | D9: =SUMIF($E$16:$F$81,"Khánh",$G$16:$G$81)+SUMIF($E$16:$F$81,"All Team",$G$16:$G$81)/5+SUMIF($E$16:$F$81,"Khánh,Rin",$G$16:$G$81)/2 -> 33 | E9: =SUMIF($E$16:$F$81,"Khánh",$H$16:$H$81)+SUMIF($E$16:$F$81,"All Team",$H$16:$H$81)/5+SUMIF($E$16:$F$81,"Khánh,Rin",$H$16:$H$81)/2 -> 33
B10: 3 | C10: Đỗ Trương Hồng Duyên | D10: =SUMIF($E$16:$F$81,"Duyên",$G$16:$G$81)+SUMIF($E$16:$F$81,"All Team",$G$16:$G$81)/5 -> 31 | E10: =SUMIF($E$16:$F$81,"Duyên",$H$16:$H$81)+SUMIF($E$16:$F$81,"All Team",$H$16:$H$81)/5 -> 32
B11: 4 | C11: Phan Dương Phương Duy | D11: =SUMIF($E$16:$F$81,"Duy",$G$16:$G$81)+SUMIF($E$16:$F$81,"All Team",$G$16:$G$81)/5 -> 31 | E11: =SUMIF($E$16:$F$81,"Duy",$H$16:$H$81)+SUMIF($E$16:$F$81,"All Team",$H$16:$H$81)/5 -> 31
B12: 5 | C12: Phan Đình Rin | D12: =SUMIF($E$16:$F$81,"Rin",$G$16:$G$81)+SUMIF($E$16:$F$81,"All Team",$G$16:$G$81)/5+SUMIF($E$16:$F$81,"Khánh,Rin",$G$16:$G$81)/2 -> 33 | E12: =SUMIF($E$16:$F$81,"Rin",$H$16:$H$81)+SUMIF($E$16:$F$81,"All Team",$H$16:$H$81)/5+SUMIF($E$16:$F$81,"Khánh,Rin",$H$16:$H$81)/2 -> 33
B13: Tổng | D13: =SUM(D8:D12) -> 161 | E13: =SUM(E8:E12) -> 163
A15: Sprint | B15: Compoment | C15: Task name | E15: Responsible Member | G15: Thực tế | H15: Ước tính | I15: 46101 | J15: 46102 | K15: 46103 | L15: 46104 | M15: 46105 | N15: 46106 | O15: 46107 | P15: 46108 | Q15: 46109 | R15: 46110 | S15: 46111 | T15: 46112 | U15: 46113 | V15: 46114 | W15: 46115 | X15: 46116 | Y15: 46117 | Z15: 46118 | AA15: 46119 | AB15: 46120 | AC15: 46121
A16: Sprint 1 | B16: Họp kế hoạch Sprint | E16: All Team | G16: 10 | H16: 10 | I16: 0 | J16: 0 | K16: 0 | L16: 0 | M16: 0 | N16: 0 | O16: 0 | P16: 0 | Q16: 0 | R16: 0 | S16: 0 | T16: 0 | U16: 0 | V16: 0 | W16: 0 | X16: 0 | Y16: 0 | Z16: 0 | AA16: 0 | AB16: 0 | AC16: 0
B17: Tạo Sprint Backlog 1 | E17: Khoa | G17: 4 | H17: 4 | I17: 4 | J17: 0 | K17: 0 | L17: 0 | M17: 0 | N17: 0 | O17: 0 | P17: 0 | Q17: 0 | R17: 0 | S17: 0 | T17: 0 | U17: 0 | V17: 0 | W17: 0 | X17: 0 | Y17: 0 | Z17: 0 | AA17: 0 | AB17: 0 | AC17: 0
B18: Tạo tài liệu kiểm thử cho Sprint | E18: Duy | G18: 4 | H18: 4 | I18: 4 | J18: 0 | K18: 0 | L18: 0 | M18: 0 | N18: 0 | O18: 0 | P18: 0 | Q18: 0 | R18: 0 | S18: 0 | T18: 0 | U18: 0 | V18: 0 | W18: 0 | X18: 0 | Y18: 0 | Z18: 0 | AA18: 0 | AB18: 0 | AC18: 0
B19: User interface design | C19: Giao diện đang nhập | E19: Duyên | G19: 1 | H19: 1 | I19: 1 | J19: 1 | K19: 0 | L19: 0 | M19: 0 | N19: 0 | O19: 0 | P19: 0 | Q19: 0 | R19: 0 | S19: 0 | T19: 0 | U19: 0 | V19: 0 | W19: 0 | X19: 0 | Y19: 0 | Z19: 0 | AA19: 0 | AB19: 0 | AC19: 0
C20: Giao diện đăng xuất | E20: Rin | G20: 1 | H20: 1 | I20: 1 | J20: 1 | K20: 0 | L20: 0 | M20: 0 | N20: 0 | O20: 0 | P20: 0 | Q20: 0 | R20: 0 | S20: 0 | T20: 0 | U20: 0 | V20: 0 | W20: 0 | X20: 0 | Y20: 0 | Z20: 0 | AA20: 0 | AB20: 0 | AC20: 0
C21: Đổi mật khẩu | E21: Khánh | G21: 1 | H21: 1 | I21: 1 | J21: 1 | K21: 0 | L21: 0 | M21: 0 | N21: 0 | O21: 0 | P21: 0 | Q21: 0 | R21: 0 | S21: 0 | T21: 0 | U21: 0 | V21: 0 | W21: 0 | X21: 0 | Y21: 0 | Z21: 0 | AA21: 0 | AB21: 0 | AC21: 0
C22: Giao diện quản lí nhân viên | E22: Khoa | G22: 1 | H22: 2 | I22: 2 | J22: 2 | K22: 0 | L22: 0 | M22: 0 | N22: 0 | O22: 0 | P22: 0 | Q22: 0 | R22: 0 | S22: 0 | T22: 0 | U22: 0 | V22: 0 | W22: 0 | X22: 0 | Y22: 0 | Z22: 0 | AA22: 0 | AB22: 0 | AC22: 0
K23: 1
C24: Giao diện quản lí tài khoản nhân viên | E24: Duy | G24: 2 | H24: 2 | I24: 2 | J24: 2 | K24: 1 | L24: 0 | M24: 0 | N24: 0 | O24: 0 | P24: 0 | Q24: 0 | R24: 0 | S24: 0 | T24: 0 | U24: 0 | V24: 0 | W24: 0 | X24: 0 | Y24: 0 | Z24: 0 | AA24: 0 | AB24: 0 | AC24: 0
C25: Giao diện quản lí phòng ban | E25: Duyên | G25: 2 | H25: 2 | I25: 2 | J25: 2 | K25: 1 | L25: 0 | M25: 0 | N25: 0 | O25: 0 | P25: 0 | Q25: 0 | R25: 0 | S25: 0 | T25: 0 | U25: 0 | V25: 0 | W25: 0 | X25: 0 | Y25: 0 | Z25: 0 | AA25: 0 | AB25: 0 | AC25: 0
C26: Giao diện bản điều khiển | E26: Rin | G26: 2 | H26: 2 | I26: 2 | J26: 2 | K26: 1 | L26: 0 | M26: 0 | N26: 0 | O26: 0 | P26: 0 | Q26: 0 | R26: 0 | S26: 0 | T26: 0 | U26: 0 | V26: 0 | W26: 0 | X26: 0 | Y26: 0 | Z26: 0 | AA26: 0 | AB26: 0 | AC26: 0
C27: Giao diện trang cá nhân | E27: Khánh | G27: 2 | H27: 2 | I27: 2 | J27: 2 | K27: 1 | L27: 0 | M27: 0 | N27: 0 | O27: 0 | P27: 0 | Q27: 0 | R27: 0 | S27: 0 | T27: 0 | U27: 0 | V27: 0 | W27: 0 | X27: 0 | Y27: 0 | Z27: 0 | AA27: 0 | AB27: 0 | AC27: 0
C28: Review all user interfaces of sprint 1 | E28: All Team | G28: 10 | H28: 10 | I28: 10 | J28: 10 | K28: 10 | L28: 10 | M28: 0 | N28: 0 | O28: 0 | P28: 0 | Q28: 0 | R28: 0 | S28: 0 | T28: 0 | U28: 0 | V28: 0 | W28: 0 | X28: 0 | Y28: 0 | Z28: 0 | AA28: 0 | AB28: 0 | AC28: 0
B29: Design test case | C29: Thiết kế cho trường kiểm thử cho đăng nhập | E29: Duy | G29: 2 | H29: 2 | I29: 2 | J29: 2 | K29: 2 | L29: 2 | M29: 2 | N29: 0 | O29: 0 | P29: 0 | Q29: 0 | R29: 0 | S29: 0 | T29: 0 | U29: 0 | V29: 0 | W29: 0 | X29: 0 | Y29: 0 | Z29: 0 | AA29: 0 | AB29: 0 | AC29: 0
C30: Kiểm thử cho trường đăng xuất | E30: Duyên | G30: 2 | H30: 2 | I30: 2 | J30: 2 | K30: 2 | L30: 2 | M30: 2 | N30: 0 | O30: 0 | P30: 0 | Q30: 0 | R30: 0 | S30: 0 | T30: 0 | U30: 0 | V30: 0 | W30: 0 | X30: 0 | Y30: 0 | Z30: 0 | AA30: 0 | AB30: 0 | AC30: 0
C31: Kiểm thử cho trường đổi mật khẩu | E31: Khoa | G31: 2 | H31: 2 | I31: 2 | J31: 2 | K31: 2 | L31: 2 | M31: 2 | N31: 1 | O31: 0 | P31: 0 | Q31: 0 | R31: 0 | S31: 0 | T31: 0 | U31: 0 | V31: 0 | W31: 0 | X31: 0 | Y31: 0 | Z31: 0 | AA31: 0 | AB31: 0 | AC31: 0
C32: Thiết kế cho trường kiểm thử quản lí nhân viên | E32: Rin | G32: 2 | H32: 2 | I32: 2 | J32: 2 | K32: 2 | L32: 2 | M32: 2 | N32: 1 | O32: 0 | P32: 0 | Q32: 0 | R32: 0 | S32: 0 | T32: 0 | U32: 0 | V32: 0 | W32: 0 | X32: 0 | Y32: 0 | Z32: 0 | AA32: 0 | AB32: 0 | AC32: 0
C33: Thiết kế cho trường kiểm thử quản lí tài khoản nhân viên | E33: Khánh | G33: 2 | H33: 2 | I33: 2 | J33: 2 | K33: 2 | L33: 2 | M33: 2 | N33: 1 | O33: 0 | P33: 0 | Q33: 0 | R33: 0 | S33: 0 | T33: 0 | U33: 0 | V33: 0 | W33: 0 | X33: 0 | Y33: 0 | Z33: 0 | AA33: 0 | AB33: 0 | AC33: 0
C34: Thiết kế cho trường kiểm thử bản điều khiển | E34: Duy | G34: 2 | H34: 2 | I34: 2 | J34: 2 | K34: 2 | L34: 2 | M34: 2 | N34: 1 | O34: 0 | P34: 0 | Q34: 0 | R34: 0 | S34: 0 | T34: 0 | U34: 0 | V34: 0 | W34: 0 | X34: 0 | Y34: 0 | Z34: 0 | AA34: 0 | AB34: 0 | AC34: 0
C35: Thiết kể quản lí phòng ban | E35: Duyên | G35: 2 | H35: 2 | I35: 2 | J35: 2 | K35: 2 | L35: 2 | M35: 2 | N35: 1 | O35: 0 | P35: 0 | Q35: 0 | R35: 0 | S35: 0 | T35: 0 | U35: 0 | V35: 0 | W35: 0 | X35: 0 | Y35: 0 | Z35: 0 | AA35: 0 | AB35: 0 | AC35: 0
C36: Thiết kế kiểm thử cho trang cá nhân | E36: Khoa | G36: 2 | H36: 2 | I36: 2 | J36: 2 | K36: 2 | L36: 2 | M36: 2 | N36: 1 | O36: 0 | P36: 0 | Q36: 0 | R36: 0 | S36: 0 | T36: 0 | U36: 0 | V36: 0 | W36: 0 | X36: 0 | Y36: 0 | Z36: 0 | AA36: 0 | AB36: 0 | AC36: 0
C37: Review all test case of sprint 1 | E37: All Team | G37: 10 | H37: 10 | I37: 10 | J37: 10 | K37: 10 | L37: 10 | M37: 10 | N37: 10 | O37: 10 | P37: 0 | Q37: 0 | R37: 0 | S37: 0 | T37: 0 | U37: 0 | V37: 0 | W37: 0 | X37: 0 | Y37: 0 | Z37: 0 | AA37: 0 | AB37: 0 | AC37: 0
B38: Coding | C38: Thiết kế font-end cho trang đăng nhập | E38: Duy | G38: 2 | H38: 2 | I38: 2 | J38: 2 | K38: 2 | L38: 2 | M38: 2 | N38: 2 | O38: 2 | P38: 2 | Q38: 0 | R38: 0 | S38: 0 | T38: 0 | U38: 0 | V38: 0 | W38: 0 | X38: 0 | Y38: 0 | Z38: 0 | AA38: 0 | AB38: 0 | AC38: 0
C39: Code back-end cho trang đăng nhập | E39: Duy | G39: 2 | H39: 2 | I39: 2 | J39: 2 | K39: 2 | L39: 2 | M39: 2 | N39: 2 | O39: 2 | P39: 2 | Q39: 0 | R39: 0 | S39: 0 | T39: 0 | U39: 0 | V39: 0 | W39: 0 | X39: 0 | Y39: 0 | Z39: 0 | AA39: 0 | AB39: 0 | AC39: 0
C40: Code chức năng đăng xuất | E40: Khoa | G40: 1 | H40: 1 | I40: 1 | J40: 1 | K40: 1 | L40: 1 | M40: 1 | N40: 1 | O40: 1 | P40: 1 | Q40: 0 | R40: 0 | S40: 0 | T40: 0 | U40: 0 | V40: 0 | W40: 0 | X40: 0 | Y40: 0 | Z40: 0 | AA40: 0 | AB40: 0 | AC40: 0
C41: Thiết kế font-end cho trang đổi mật khẩu | E41: Khoa | G41: 2 | H41: 2 | I41: 2 | J41: 2 | K41: 2 | L41: 2 | M41: 2 | N41: 2 | O41: 2 | P41: 2 | Q41: 0 | R41: 0 | S41: 0 | T41: 0 | U41: 0 | V41: 0 | W41: 0 | X41: 0 | Y41: 0 | Z41: 0 | AA41: 0 | AB41: 0 | AC41: 0
...

Sheet Sprint 2
A1: Project name: | C1: XÂY DỰNG HỆ THỐNG QUẢN LÝ NHÂN SỰ CHO DOANH NGHIỆP NHỎ TÍCH HỢP CHATBOT AI HỖ TRỢ TRA CỨU THÔNG TIN | F1: Kết thúc
A2: Module name: | C2: Sprint 2 | F2: Tăng ca
A3: Start date: | C3: 46122 | F3: Muộn
A4: End date: | C4: 46142 | F4: Chậm tiến độ
F5: Trước thời hạn
B6: SPRINT 1 REPORT
B7: No | C7: Thành viên | D7: Thực tế | E7: Ước tính
B8: 1 | C8: Lê Xuân Khoa | D8: =SUMIF(E16:$F$69,"Khoa",$G$16:$G$69)+SUMIF(E16:$F$69,"All Team",$G$16:$G$69)/5 -> 28 | E8: =SUMIF($E$16:$F$69,"Khoa",$H$16:$H$69)+SUMIF($E$16:$F$69,"All Team",$H$16:$H$69)/5 -> 28
B9: 2 | C9: Hoàng Minh Khánh | D9: =SUMIF($E$16:$F$69,"Khánh",$G$16:$G$69)+SUMIF($E$16:$F$69,"All Team",$G$16:$G$69)/5 -> 27 | E9: =SUMIF($E$16:$F$69,"Khánh",$H$16:$H$69)+SUMIF($E$16:$F$69,"All Team",$H$16:$H$69)/5 -> 27
B10: 3 | C10: Đỗ Trương Hồng Duyên | D10: =SUMIF(E16:$F$69,"Duyên",$G$16:$G$69)+SUMIF(E16:$F$69,"All Team",$G$16:$G$69)/5 -> 28 | E10: =SUMIF($E$16:$F$69,"Duyên",$H$16:$H$69)+SUMIF($E$16:$F$69,"All Team",$H$16:$H$69)/5 -> 28
B11: 4 | C11: Phan Dương Phương Duy | D11: =SUMIF(E16:$F$69,"Duy",$G$16:$G$69)+SUMIF(E16:$F$69,"All Team",$G$16:$G$69)/5 -> 27 | E11: =SUMIF($E$16:$F$69,"Duy",$H$16:$H$69)+SUMIF($E$16:$F$69,"All Team",$H$16:$H$69)/5 -> 28
B12: 5 | C12: Phan Đình Rin | D12: =SUMIF(E16:$F$69,"Rin",$G$16:$G$69)+SUMIF(E16:$F$69,"All Team",$G$16:$G$69)/5 -> 31 | E12: =SUMIF($E$16:$F$69,"Rin",$H$16:$H$69)+SUMIF($E$16:$F$69,"All Team",$H$16:$H$69)/5 -> 31
B13: Tổng | D13: =SUM(D8:D12) -> 141 | E13: =SUM(E8:E12) -> 142
A15: Sprint | B15: Compoment | C15: Task name | E15: Responsible Member | G15: Thực tế | H15: Ước tính | I15: 46122 | J15: 46123 | K15: 46124 | L15: 46125 | M15: 46126 | N15: 46127 | O15: 46128 | P15: 46129 | Q15: 46130 | R15: 46131 | S15: 46132 | T15: 46133 | U15: 46134 | V15: 46135 | W15: 46136 | X15: 46137 | Y15: 46138 | Z15: 46139 | AA15: 46140 | AB15: 46141 | AC15: 46142
A16: sprint 2 | B16: Họp kế hoạch Sprint | E16: All Team | G16: 10 | H16: 10 | I16: 0 | J16: 0 | K16: 0 | L16: 0 | M16: 0 | N16: 0 | O16: 0 | P16: 0 | Q16: 0 | R16: 0 | S16: 0 | T16: 0 | U16: 0 | V16: 0 | W16: 0 | X16: 0 | Y16: 0 | Z16: 0 | AA16: 0 | AB16: 0 | AC16: 0
B17: Tạo Sprint Backlog 2 | E17: Duy | G17: 4 | H17: 4 | I17: 0 | J17: 0 | K17: 0 | L17: 0 | M17: 0 | N17: 0 | O17: 0 | P17: 0 | Q17: 0 | R17: 0 | S17: 0 | T17: 0 | U17: 0 | V17: 0 | W17: 0 | X17: 0 | Y17: 0 | Z17: 0 | AA17: 0 | AB17: 0 | AC17: 0
B18: Tạo tài liệu kiểm thử cho Sprint | E18: Duy | G18: 4 | H18: 4 | I18: 2 | J18: 0 | K18: 0 | L18: 0 | M18: 0 | N18: 0 | O18: 0 | P18: 0 | Q18: 0 | R18: 0 | S18: 0 | T18: 0 | U18: 0 | V18: 0 | W18: 0 | X18: 0 | Y18: 0 | Z18: 0 | AA18: 0 | AB18: 0 | AC18: 0
B19: User interface design | C19: Giao diện lịch sử chấm công | E19: Duyên | G19: 2 | H19: 2 | I19: 2 | J19: 2 | K19: 0 | L19: 0 | M19: 0 | N19: 0 | O19: 0 | P19: 0 | Q19: 0 | R19: 0 | S19: 0 | T19: 0 | U19: 0 | V19: 0 | W19: 0 | X19: 0 | Y19: 0 | Z19: 0 | AA19: 0 | AB19: 0 | AC19: 0
C20: Giao diện quản lí chấm công | E20: Khoa | G20: 2 | H20: 2 | I20: 2 | J20: 2 | K20: 0 | L20: 0 | M20: 0 | N20: 0 | O20: 0 | P20: 0 | Q20: 0 | R20: 0 | S20: 0 | T20: 0 | U20: 0 | V20: 0 | W20: 0 | X20: 0 | Y20: 0 | Z20: 0 | AA20: 0 | AB20: 0 | AC20: 0
C21: Giao diện quản lí đơn nghỉ phép | E21: Rin | G21: 2 | H21: 2 | I21: 2 | J21: 2 | K21: 0 | L21: 0 | M21: 0 | N21: 0 | O21: 0 | P21: 0 | Q21: 0 | R21: 0 | S21: 0 | T21: 0 | U21: 0 | V21: 0 | W21: 0 | X21: 0 | Y21: 0 | Z21: 0 | AA21: 0 | AB21: 0 | AC21: 0
C22: Giao diện xin nghỉ phép | E22: Khánh | G22: 2 | H22: 2 | I22: 2 | J22: 2 | K22: 0 | L22: 0 | M22: 0 | N22: 0 | O22: 0 | P22: 0 | Q22: 0 | R22: 0 | S22: 0 | T22: 0 | U22: 0 | V22: 0 | W22: 0 | X22: 0 | Y22: 0 | Z22: 0 | AA22: 0 | AB22: 0 | AC22: 0
C23: Giao diện lịch sử lương | E23: Duyên | G23: 2 | H23: 2 | I23: 2 | J23: 2 | K23: 0 | L23: 0 | M23: 0 | N23: 0 | O23: 0 | P23: 0 | Q23: 0 | R23: 0 | S23: 0 | T23: 0 | U23: 0 | V23: 0 | W23: 0 | X23: 0 | Y23: 0 | Z23: 0 | AA23: 0 | AB23: 0 | AC23: 0
C24: Giao diện quản lí lương | E24: Khoa | G24: 2 | H24: 2 | I24: 2 | J24: 2 | K24: 0 | L24: 0 | M24: 0 | N24: 0 | O24: 0 | P24: 0 | Q24: 0 | R24: 0 | S24: 0 | T24: 0 | U24: 0 | V24: 0 | W24: 0 | X24: 0 | Y24: 0 | Z24: 0 | AA24: 0 | AB24: 0 | AC24: 0
C25: Review all user interfaces of sprint 2 | E25: All Team | G25: 10 | H25: 10 | I25: 10 | J25: 10 | K25: 10 | L25: 0 | M25: 0 | N25: 0 | O25: 0 | P25: 0 | Q25: 0 | R25: 0 | S25: 0 | T25: 0 | U25: 0 | V25: 0 | W25: 0 | X25: 0 | Y25: 0 | Z25: 0 | AA25: 0 | AB25: 0 | AC25: 0
B26: Design test case | C26: Thiết kế cho trường kiểm thử cho lịch sử chấm công | E26: Duyên | G26: 2 | H26: 2 | I26: 2 | J26: 2 | K26: 2 | L26: 2 | M26: 0 | N26: 0 | O26: 0 | P26: 0 | Q26: 0 | R26: 0 | S26: 0 | T26: 0 | U26: 0 | V26: 0 | W26: 0 | X26: 0 | Y26: 0 | Z26: 0 | AA26: 0 | AB26: 0 | AC26: 0
C27: Kiểm thử cho trường quản lí chấm công | E27: Khoa | G27: 2 | H27: 2 | I27: 2 | J27: 2 | K27: 2 | L27: 2 | M27: 0 | N27: 0 | O27: 0 | P27: 0 | Q27: 0 | R27: 0 | S27: 0 | T27: 0 | U27: 0 | V27: 0 | W27: 0 | X27: 0 | Y27: 0 | Z27: 0 | AA27: 0 | AB27: 0 | AC27: 0
C28: Kiểm thử cho trường xin nghỉ phép | E28: Rin | G28: 2 | H28: 2 | I28: 2 | J28: 2 | K28: 2 | L28: 2 | M28: 0 | N28: 0 | O28: 0 | P28: 0 | Q28: 0 | R28: 0 | S28: 0 | T28: 0 | U28: 0 | V28: 0 | W28: 0 | X28: 0 | Y28: 0 | Z28: 0 | AA28: 0 | AB28: 0 | AC28: 0
C29: Thiết kế cho trường kiểm thử quản lí đơn xin nghỉ phép | E29: Khánh | G29: 2 | H29: 2 | I29: 2 | J29: 2 | K29: 2 | L29: 2 | M29: 0 | N29: 0 | O29: 0 | P29: 0 | Q29: 0 | R29: 0 | S29: 0 | T29: 0 | U29: 0 | V29: 0 | W29: 0 | X29: 0 | Y29: 0 | Z29: 0 | AA29: 0 | AB29: 0 | AC29: 0
C30: Thiết kế cho trường kiểm thử lịch sử lương | E30: Duy | G30: 2 | H30: 2 | I30: 2 | J30: 2 | K30: 2 | L30: 2 | M30: 0 | N30: 0 | O30: 0 | P30: 0 | Q30: 0 | R30: 0 | S30: 0 | T30: 0 | U30: 0 | V30: 0 | W30: 0 | X30: 0 | Y30: 0 | Z30: 0 | AA30: 0 | AB30: 0 | AC30: 0
C31: Thiết kế cho trường kiểm thử quản lí lương | E31: Duyên | G31: 2 | H31: 2 | I31: 2 | J31: 2 | K31: 2 | L31: 2 | M31: 0 | N31: 0 | O31: 0 | P31: 0 | Q31: 0 | R31: 0 | S31: 0 | T31: 0 | U31: 0 | V31: 0 | W31: 0 | X31: 0 | Y31: 0 | Z31: 0 | AA31: 0 | AB31: 0 | AC31: 0
C32: Review all test case of sprint 2 | E32: All Team | G32: 10 | H32: 10 | I32: 10 | J32: 10 | K32: 10 | L32: 10 | M32: 10 | N32: 0 | O32: 0 | P32: 0 | Q32: 0 | R32: 0 | S32: 0 | T32: 0 | U32: 0 | V32: 0 | W32: 0 | X32: 0 | Y32: 0 | Z32: 0 | AA32: 0 | AB32: 0 | AC32: 0
B33: Coding | C33: Thiết kế font-end cho lịch sử chấm công | E33: Rin | G33: 1 | H33: 2 | I33: 2 | J33: 2 | K33: 2 | L33: 2 | M33: 2 | N33: 2 | O33: 0 | P33: 0 | Q33: 0 | R33: 0 | S33: 0 | T33: 0 | U33: 0 | V33: 0 | W33: 0 | X33: 0 | Y33: 0 | Z33: 0 | AA33: 0 | AB33: 0 | AC33: 0
O34: 1
C35: Code back-end cho lịch sử chấm công | E35: Rin | G35: 3 | H35: 3 | I35: 3 | J35: 3 | K35: 3 | L35: 3 | M35: 3 | N35: 3 | O35: 3 | P35: 0 | Q35: 0 | R35: 0 | S35: 0 | T35: 0 | U35: 0 | V35: 0 | W35: 0 | X35: 0 | Y35: 0 | Z35: 0 | AA35: 0 | AB35: 0 | AC35: 0
C36: Thiết kê font-end cho trang quản lí chấm công | E36: Duy | G36: 1 | H36: 2 | I36: 2 | J36: 2 | K36: 2 | L36: 2 | M36: 2 | N36: 2 | O36: 0 | P36: 0 | Q36: 0 | R36: 0 | S36: 0 | T36: 0 | U36: 0 | V36: 0 | W36: 0 | X36: 0 | Y36: 0 | Z36: 0 | AA36: 0 | AB36: 0 | AC36: 0
O37: 1
C38: Code back-end cho trang quản lí chấm công | E38: Duy | G38: 3 | H38: 3 | I38: 3 | J38: 3 | K38: 3 | L38: 3 | M38: 3 | N38: 3 | O38: 3 | P38: 3 | Q38: 0 | R38: 3 | S38: 0 | T38: 0 | U38: 0 | V38: 0 | W38: 0 | X38: 0 | Y38: 0 | Z38: 0 | AA38: 0 | AB38: 0 | AC38: 0
C39: Thiết kế font-end cho trang xin nghỉ phép | E39: Duyên | G39: 2 | H39: 2 | I39: 2 | J39: 2 | K39: 2 | L39: 2 | M39: 2 | N39: 2 | O39: 2 | P39: 2 | Q39: 0 | R39: 0 | S39: 0 | T39: 0 | U39: 0 | V39: 0 | W39: 0 | X39: 0 | Y39: 0 | Z39: 0 | AA39: 0 | AB39: 0 | AC39: 0
C40: Code back-end cho trang xin nghỉ phép | E40: Duyên | G40: 3 | H40: 3 | I40: 3 | J40: 3 | K40: 3 | L40: 3 | M40: 3 | N40: 3 | O40: 3 | P40: 3 | Q40: 3 | R40: 0
C41: Thiết kế font-end cho trang quản lí đơn nghỉ phép | E41: Khoa | G41: 2 | H41: 2 | I41: 2 | J41: 2 | K41: 2 | L41: 2 | M41: 2 | N41: 2 | O41: 2 | P41: 2 | Q41: 2 | R41: 0 | S41: 0 | T41: 0 | U41: 0 | V41: 0 | W41: 0 | X41: 0 | Y41: 0 | Z41: 0 | AA41: 0 | AB41: 0 | AC41: 0
...

Sheet Sprint 3
A1: Project name: | C1: XÂY DỰNG HỆ THỐNG QUẢN LÝ NHÂN SỰ CHO DOANH NGHIỆP NHỎ TÍCH HỢP CHATBOT AI HỖ TRỢ TRA CỨU THÔNG TIN | F1: Kết thúc
A2: Module name: | C2: Sprint 3 | F2: Tăng ca
A3: Start date: | C3: 46143 | F3: Muộn
A4: End date: | C4: 46157 | F4: Chậm tiến độ
F5: Trước thời hạn
B6: SPRINT 1 REPORT
B7: No | C7: Thành viên | D7: Thực tế | E7: Ước tính
B8: 1 | C8: Lê Xuân Khoa | D8: =SUMIF(E16:$F$71,"Khoa",$G$16:$G$71)+SUMIF(E16:$F$71,"All Team",$G$16:$G$71)/5+SUMIF(E16:$F$71,"Khoa,Khánh,Duyên",$G$16:$G$71)/3 -> 30 | E8: =SUMIF($E$16:$F$71,"Khoa",$G$16:$G$71)+SUMIF($E$16:$F$71,"All Team",$G$16:$G$71)/5+SUMIF($E$16:$F$71,"Khoa,Khánh,Duyên",$G$16:$G$71)/3 -> 30
B9: 2 | C9: Hoàng Minh Khánh | D9: =SUMIF(E16:$F$71,"Khánh",$G$16:$G$71)+SUMIF(E16:$F$71,"All Team",$G$16:$G$71)/5+SUMIF(E16:$F$71,"Khoa,Khánh,Duyên",$G$16:$G$71)/3+SUMIF(E16:$F$71,"Khánh,Duyên",$G$16:$G$71)/3 -> 28 | E9: =SUMIF($E$16:$F$71,"Khánh",$G$16:$G$71)+SUMIF($E$16:$F$71,"All Team",$G$16:$G$71)/5+SUMIF($E$16:$F$71,"Khoa,Khánh,Duyên",$G$16:$G$71)/3+SUMIF($E$16:$F$71,"Khánh,Duyên",$G$16:$G$71)/2 -> 28
B10: 3 | C10: Đỗ Trương Hồng Duyên | D10: =SUMIF(E16:$F$71,"Duyên",$G$16:$G$71)+SUMIF(E16:$F$71,"All Team",$G$16:$G$71)/5+SUMIF(E16:$F$71,"Khoa,Khánh,Duyên",$G$16:$G$71)/3+SUMIF(E16:$F$71,"Khánh,Duyên",$G$16:$G$71)/3 -> 29 | E10: =SUMIF($E$16:$F$71,"Duyên",$G$16:$G$71)+SUMIF($E$16:$F$71,"All Team",$G$16:$G$71)/5+SUMIF($E$16:$F$71,"Khoa,Khánh,Duyên",$G$16:$G$71)/3+SUMIF($E$16:$F$71,"Khánh,Duyên",$G$16:$G$71)/2 -> 29
B11: 4 | C11: Phan Dương Phương Duy | D11: =SUMIF(E16:$F$71,"Duy",$G$16:$G$71)+SUMIF(E16:$F$71,"All Team",$G$16:$G$71)/5 -> 30 | E11: =SUMIF($E$16:$F$71,"Duy",$G$16:$G$71)+SUMIF($E$16:$F$71,"All Team",$G$16:$G$71)/5 -> 30
B12: 5 | C12: Phan Đình Rin | D12: =SUMIF(E16:$F$71,"Rin",$G$16:$G$71)+SUMIF(E16:$F$71,"All Team",$G$16:$G$71)/5 -> 27 | E12: =SUMIF($E$16:$F$71,"Rin",$G$16:$G$71)+SUMIF($E$16:$F$71,"All Team",$G$16:$G$71)/5 -> 27
B13: Tổng | D13: =SUM(D8:D12) -> 144 | E13: =SUM(E8:E12) -> 144
A15: Sprint | B15: Compoment | C15: Task name | E15: Responsible Member | G15: Thực tế | H15: Ước tính | I15: 46143 | J15: 46144 | K15: 46145 | L15: 46146 | M15: 46147 | N15: 46148 | O15: 46149 | P15: 46150 | Q15: 46151 | R15: 46152 | S15: 46153 | T15: 46154 | U15: 46155 | V15: 46156 | W15: 46157
A16: Sprint 3 | B16: Họp kế hoạch Sprint | E16: All Team | G16: 10 | H16: 10 | I16: 0 | J16: 0 | K16: 0 | L16: 0 | M16: 0 | N16: 0 | O16: 0 | P16: 0 | Q16: 0 | R16: 0 | S16: 0 | T16: 0 | U16: 0 | V16: 0 | W16: 0
B17: Tạo Sprint Backlog 3 | E17: Rin | G17: 4 | H17: 4 | I17: 0 | J17: 0 | K17: 0 | L17: 0 | M17: 0 | N17: 0 | O17: 0 | P17: 0 | Q17: 0 | R17: 0 | S17: 0 | T17: 0 | U17: 0 | V17: 0 | W17: 0
B18: Tạo tài liệu kiểm thử cho Sprint | E18: Duy | G18: 4 | H18: 4 | I18: 4 | J18: 0 | K18: 0 | L18: 0 | M18: 0 | N18: 0 | O18: 0 | P18: 0 | Q18: 0 | R18: 0 | S18: 0 | T18: 0 | U18: 0 | V18: 0 | W18: 0
B19: User interface design | C19: Giao diện quản lí và gửi thông báo | E19: Duy | G19: 2 | H19: 2 | I19: 2 | J19: 2 | K19: 0 | L19: 0 | M19: 0 | N19: 0 | O19: 0 | P19: 0 | Q19: 0 | R19: 0 | S19: 0 | T19: 0 | U19: 0 | V19: 0 | W19: 0
C20: Giao diện quản lí hợp đồng | E20: Duyên | G20: 2 | H20: 2 | I20: 2 | J20: 2 | K20: 0 | L20: 0 | M20: 0 | N20: 0 | O20: 0 | P20: 0 | Q20: 0 | R20: 0 | S20: 0 | T20: 0 | U20: 0 | V20: 0 | W20: 0
C21: Giao diện hợp đồng cá nhân | E21: Khoa | G21: 2 | H21: 2 | I21: 2 | J21: 2 | K21: 0 | L21: 0 | M21: 0 | N21: 0 | O21: 0 | P21: 0 | Q21: 0 | R21: 0 | S21: 0 | T21: 0 | U21: 0 | V21: 0 | W21: 0
C22: Giao diện danh sách tuyển dụng | E22: Khánh | G22: 1 | H22: 2 | I22: 2 | J22: 2 | K22: 0 | L22: 0 | M22: 0 | N22: 0 | O22: 0 | P22: 0 | Q22: 0 | R22: 0 | S22: 0 | T22: 0 | U22: 0 | V22: 0 | W22: 0
K23: 1
C24: Giao diện quản lí tin tuyển dụng | E24: Rin | G24: 2 | H24: 2 | I24: 2 | J24: 2 | K24: 0 | L24: 0 | M24: 0 | N24: 0 | O24: 0 | P24: 0 | Q24: 0 | R24: 0 | S24: 0 | T24: 0 | U24: 0 | V24: 0 | W24: 0
C25: Giao diện cửa sổ chatbot | E25: Khoa | G25: 1 | H25: 2 | I25: 2 | J25: 2 | K25: 0 | L25: 0 | M25: 0 | N25: 0 | O25: 0 | P25: 0 | Q25: 0 | R25: 0 | S25: 0 | T25: 0 | U25: 0 | V25: 0 | W25: 0
K26: 1
C27: Review all user interfaces of sprint 3 | E27: All Team | G27: 10 | H27: 10 | I27: 10 | J27: 10 | K27: 10 | L27: 0 | M27: 0 | N27: 0 | O27: 0 | P27: 0 | Q27: 0 | R27: 0 | S27: 0 | T27: 0 | U27: 0 | V27: 0 | W27: 0
B28: Design test case | C28: Thiết kế cho trường kiểm thử cho quản lí và gửi thông báo | E28: Duyên | G28: 2 | H28: 2 | I28: 2 | J28: 2 | K28: 2 | L28: 2 | M28: 0 | N28: 0 | O28: 0 | P28: 0 | Q28: 0 | R28: 0 | S28: 0 | T28: 0 | U28: 0 | V28: 0 | W28: 0
C29: Kiểm thử cho trường quản lí hợp đồng | E29: Khoa | G29: 2 | H29: 2 | I29: 2 | J29: 2 | K29: 2 | L29: 2 | M29: 0 | N29: 0 | O29: 0 | P29: 0 | Q29: 0 | R29: 0 | S29: 0 | T29: 0 | U29: 0 | V29: 0 | W29: 0
C30: Kiểm thử cho trường hợp đồng cá nhân | E30: Khánh | G30: 2 | H30: 2 | I30: 2 | J30: 2 | K30: 2 | L30: 2 | M30: 0 | N30: 0 | O30: 0 | P30: 0 | Q30: 0 | R30: 0 | S30: 0 | T30: 0 | U30: 0 | V30: 0 | W30: 0
C31: Thiết kế cho trường kiểm thử danh sách tuyển dụng | E31: Rin | G31: 2 | H31: 2 | I31: 2 | J31: 2 | K31: 2 | L31: 2 | M31: 0 | N31: 0 | O31: 0 | P31: 0 | Q31: 0 | R31: 0 | S31: 0 | T31: 0 | U31: 0 | V31: 0 | W31: 0
C32: Thiết kế cho trường kiểm thử quản lí tin tuyển dụng | E32: Duy | G32: 2 | H32: 2 | I32: 2 | J32: 2 | K32: 2 | L32: 2 | M32: 0 | N32: 0 | O32: 0 | P32: 0 | Q32: 0 | R32: 0 | S32: 0 | T32: 0 | U32: 0 | V32: 0 | W32: 0
C33: Thiết kế cho trường kiểm thử cửa số chatbot | E33: Duyên | G33: 1 | H33: 2 | I33: 2 | J33: 2 | K33: 2 | L33: 2 | M33: 0 | N33: 0 | O33: 0 | P33: 0 | Q33: 0 | R33: 0 | S33: 0 | T33: 0 | U33: 0 | V33: 0 | W33: 0
M34: 1
C35: Review all test case of sprint 3 | E35: All Team | G35: 10 | H35: 10 | I35: 10 | J35: 10 | K35: 10 | L35: 10 | M35: 10 | N35: 0 | O35: 0 | P35: 0 | Q35: 0 | R35: 0 | S35: 0 | T35: 0 | U35: 0 | V35: 0 | W35: 0
B36: Coding | C36: Thiết kế font-end cho quản lí và gửi thông báo | E36: Duyên | G36: 2 | H36: 2 | I36: 2 | J36: 2 | K36: 2 | L36: 2 | M36: 2 | N36: 2 | O36: 0 | P36: 0 | Q36: 0 | R36: 0 | S36: 0 | T36: 0 | U36: 0 | V36: 0 | W36: 0
C37: Code back-end cho quản lí và gửi thông báo | E37: Duyên | G37: 3 | H37: 3 | I37: 3 | J37: 3 | K37: 3 | L37: 3 | M37: 3 | N37: 3 | O37: 3 | P37: 0 | Q37: 0 | R37: 0 | S37: 0 | T37: 0 | U37: 0 | V37: 0 | W37: 0
C38: Thiết kế font-end cho trang quản lí hợp đồng | E38: Duy | G38: 2 | H38: 2 | I38: 2 | J38: 2 | K38: 2 | L38: 2 | M38: 2 | N38: 2 | O38: 0 | P38: 0 | Q38: 0 | R38: 0 | S38: 0 | T38: 0 | U38: 0 | V38: 0 | W38: 0
C39: Code back-end cho trang quản lí hợp đồng | E39: Duy | G39: 4 | H39: 3 | I39: 3 | J39: 3 | K39: 3 | L39: 3 | M39: 3 | N39: 3 | O39: 3 | P39: 0 | Q39: 0 | R39: 0 | S39: 0 | T39: 0 | U39: 0 | V39: 0 | W39: 0
P40: 1
C41: Thiết kế font-end cho trang hợp đồng cá nhân | E41: Khánh | G41: 2 | H41: 2 | I41: 2 | J41: 2 | K41: 2 | L41: 2 | M41: 2 | N41: 2 | O41: 0 | P41: 0 | Q41: 0 | R41: 0 | S41: 0 | T41: 0 | U41: 0 | V41: 0 | W41: 0
...

Sheet ToTal
A1: SPRINT BACKLOG REPORT
B2: Khoa | D2: Khánh | F2: Duyên | H2: Duy | J2: Rin
B3: Thực tế | C3: Ước tính | D3: Thực tế | E3: Ước tính | F3: Thực tế | G3: Ước tính | H3: Thực tế | I3: Ước tính | J3: Thực tế | K3: Ước tính
A4: Sprint 1 | B4: ='Sprint 1'!D8 -> 33 | C4: ='Sprint 1'!E8 -> 34 | D4: ='Sprint 1'!D9 -> 33 | E4: ='Sprint 1'!E9 -> 33 | F4: ='Sprint 1'!D10 -> 31 | G4: ='Sprint 1'!E10 -> 32 | H4: ='Sprint 1'!D11 -> 31 | I4: ='Sprint 1'!E11 -> 31 | J4: ='Sprint 1'!D12 -> 33 | K4: ='Sprint 1'!E12 -> 33
A5: Sprint 2 | B5: ='Sprint 2'!D8 -> 28 | C5: ='Sprint 2'!E8 -> 28 | D5: ='Sprint 2'!D9 -> 27 | E5: ='Sprint 2'!E9 -> 27 | F5: ='Sprint 2'!D10 -> 28 | G5: ='Sprint 2'!E10 -> 28 | H5: ='Sprint 2'!D11 -> 27 | I5: ='Sprint 2'!E11 -> 28 | J5: ='Sprint 2'!D12 -> 31 | K5: ='Sprint 2'!E12 -> 31
A6: Sprint 3 | B6: ='Sprint 3'!D8 -> 30 | C6: ='Sprint 3'!E8 -> 30 | D6: ='Sprint 3'!D9 -> 28 | E6: ='Sprint 3'!E9 -> 28 | F6: ='Sprint 3'!D10 -> 29 | G6: ='Sprint 3'!E10 -> 29 | H6: ='Sprint 3'!D11 -> 30 | I6: ='Sprint 3'!E11 -> 30 | J6: ='Sprint 3'!D12 -> 27 | K6: ='Sprint 3'!E12 -> 27
A7: Tổng | B7: =SUM(B4:B6) -> 91 | C7: =SUM(C4:C6) -> 92 | D7: =SUM(D4:D6) -> 88 | E7: =SUM(E4:E6) -> 88 | F7: =SUM(F4:F6) -> 88 | G7: =SUM(G4:G6) -> 89 | H7: =SUM(H4:H6) -> 88 | I7: =SUM(I4:I6) -> 89 | ... K7: =SUM(K4:K6) -> 91
E10: FINAL TOTAL
E11: Thực tế | F11: =SUMIF($B$3:$K$3,"Thực tế",$B$7:$K$7) -> 446
E12: Ước tính | F12: =SUMIF($B$3:$K$3,"Ước tính",$B$7:$K$7) -> 449
